Workbook

Sheet 노동2603실적(총괄)
A3: (6.1) 總括
A4: 1) 任職員 包含 | O4: 46082
K5: (單位 : 阡Won, 名, %)
A6: 區 分 | B6: 算 式 | C6: =$O$4 -> 46082 | E6: =$O$4 -> 46082 | G6: =$O$4 -> 46082 | I6: 累計 實績 | K6: 備考
C7: 資料 | D7: 指標 | E7: 資料 | F7: 指標 | G7: 資料 | H7: 指標 | I7: 資料 | J7: 指標 | O7: ='노동2603실적(사업부별)'!N7 -> 46023 | P7: ='노동2603실적(사업부별)'!O7 -> 46054 | Q7: ='노동2603실적(사업부별)'!P7 -> 46082 | R7: ='노동2603실적(사업부별)'!Q7 -> 46113 | S7: ='노동2603실적(사업부별)'!R7 -> 46143 | T7: ='노동2603실적(사업부별)'!S7 -> 46174 | U7: ='노동2603실적(사업부별)'!T7 -> 46204 | V7: ='노동2603실적(사업부별)'!U7 -> 46235 | ... Z7: ='노동2603실적(사업부별)'!Y7 -> 46357
A8: 附加價値率 | B8: 附加價値額 | C8: 1243891.2 | D8: =C8/C9 -> 0.24976556 | E8: 1161484 | F8: =E8/E9 -> 0.24772586 | G8: ='노동2603실적(사업부별)'!$G$8 -> 1156248 | H8: =G8/G9 -> 0.23849129 | I8: =SUBTOTAL(109,$O$8:$Z$8) -> 2948182 | J8: =I8/I9 -> 0.23882398 | O8: ='노동2603실적(사업부별)'!N$8 -> 923950 | P8: ='노동2603실적(사업부별)'!O$8 -> 867984 | Q8: ='노동2603실적(사업부별)'!P$8 -> 1156248 | R8: ='노동2603실적(사업부별)'!Q$8 -> 0 | S8: ='노동2603실적(사업부별)'!R$8 -> 0 | T8: ='노동2603실적(사업부별)'!S$8 -> 0 | U8: ='노동2603실적(사업부별)'!T$8 -> 0 | V8: ='노동2603실적(사업부별)'!U$8 -> 0 | ... Z8: ='노동2603실적(사업부별)'!Y$8 -> 0
B9: ÷ 賣出額 | C9: 4980235 | E9: 4688586 | G9: ='노동2603실적(사업부별)'!$G$9 -> 4848177 | I9: =SUBTOTAL(109,$O$9:$Z$9) -> 12344581 | O9: ='노동2603실적(사업부별)'!N$9 -> 3925072 | P9: ='노동2603실적(사업부별)'!O$9 -> 3571332 | Q9: ='노동2603실적(사업부별)'!P$9 -> 4848177 | R9: ='노동2603실적(사업부별)'!Q$9 -> 0 | S9: ='노동2603실적(사업부별)'!R$9 -> 0 | T9: ='노동2603실적(사업부별)'!S$9 -> 0 | U9: ='노동2603실적(사업부별)'!T$9 -> 0 | V9: ='노동2603실적(사업부별)'!U$9 -> 0 | ... Z9: ='노동2603실적(사업부별)'!Y$9 -> 0
A10: 勞動生産性 | B10: 附加價値額 | C10: =$C$8 -> 1243891.2 | D10: =C10/C11 -> 12195.012 | E10: =$E$8 -> 1161484 | F10: =E10/E11 -> 11387.098 | G10: =$G$8 -> 1156248 | H10: =G10/G11 -> 11335.765 | I10: =$I$8 -> 2948182 | J10: =I10/I11 -> 9572.0195 | O10: =O7 -> 46023 | P10: =P7 -> 46054 | Q10: =Q7 -> 46082 | R10: =R7 -> 46113 | S10: =S7 -> 46143 | T10: =T7 -> 46174 | U10: =U7 -> 46204 | V10: =V7 -> 46235 | ... Z10: =Z7 -> 46357
B11: ÷ 常時 從業員數 | C11: ='노동2603실적(사업부별)'!$G$11 -> 102 | E11: =$C$11 -> 102 | G11: ='노동2603실적(사업부별)'!$G$11 -> 102 | I11: =SUBTOTAL(109,$O$11:$Z$11) -> 308 | O11: ='노동2603실적(사업부별)'!N$11 -> 103 | P11: ='노동2603실적(사업부별)'!O$11 -> 103 | Q11: ='노동2603실적(사업부별)'!P$11 -> 102 | R11: ='노동2603실적(사업부별)'!Q$11 -> 0 | S11: ='노동2603실적(사업부별)'!R$11 -> 0 | T11: ='노동2603실적(사업부별)'!S$11 -> 0 | U11: ='노동2603실적(사업부별)'!T$11 -> 0 | V11: ='노동2603실적(사업부별)'!U$11 -> 0 | ... Z11: ='노동2603실적(사업부별)'!Y$11 -> 0
A12: 勤勞所得 配分率 | B12: 勞務費,給與,賞與 | C12: 403457.34 | D12: =C12/C13 -> 0.32435099 | E12: 393395 | F12: =E12/E13 -> 0.33870032 | G12: ='노동2603실적(사업부별)'!$G$12 -> 360521 | H12: =G12/G13 -> 0.31180249 | I12: =SUBTOTAL(109,$O$12:$Z$12)+L12 -> 1099396 | J12: =I12/I13 -> 0.37290642 | O12: ='노동2603실적(사업부별)'!N$12 -> 371215 | P12: ='노동2603실적(사업부별)'!O$12 -> 367660 | Q12: ='노동2603실적(사업부별)'!P$12 -> 360521 | R12: ='노동2603실적(사업부별)'!Q$12 -> 0 | S12: ='노동2603실적(사업부별)'!R$12 -> 0 | T12: ='노동2603실적(사업부별)'!S$12 -> 0 | U12: ='노동2603실적(사업부별)'!T$12 -> 0 | V12: ='노동2603실적(사업부별)'!U$12 -> 0 | ... Z12: ='노동2603실적(사업부별)'!Y$12 -> 0
B13: ÷ 附加價値額 | C13: =$C$8 -> 1243891.2 | E13: =$E$8 -> 1161484 | G13: =$G$8 -> 1156248 | I13: =$I$8 -> 2948182 | O13: =O7 -> 46023 | P13: =P7 -> 46054 | Q13: =Q7 -> 46082 | R13: =R7 -> 46113 | S13: =S7 -> 46143 | T13: =T7 -> 46174 | U13: =U7 -> 46204 | V13: =V7 -> 46235 | ... Z13: =Z7 -> 46357
B14: 退職, 福利費 | C14: 58835.79 | D14: =C14/C15 -> 0.047299788 | E14: 50096 | F14: =E14/E15 -> 0.043131029 | G14: ='노동2603실적(사업부별)'!$G$14 -> 62018 | H14: =G14/G15 -> 0.053637282 | I14: =SUBTOTAL(109,$O$14:$Z$14) -> 165585 | J14: =I14/I15 -> 0.056165121 | O14: ='노동2603실적(사업부별)'!N$14 -> 48058 | P14: ='노동2603실적(사업부별)'!O$14 -> 55509 | Q14: ='노동2603실적(사업부별)'!P$14 -> 62018 | R14: ='노동2603실적(사업부별)'!Q$14 -> 0 | S14: ='노동2603실적(사업부별)'!R$14 -> 0 | T14: ='노동2603실적(사업부별)'!S$14 -> 0 | U14: ='노동2603실적(사업부별)'!T$14 -> 0 | V14: ='노동2603실적(사업부별)'!U$14 -> 0 | ... Z14: ='노동2603실적(사업부별)'!Y$14 -> 0
B15: ÷ 附加價値額 | C15: =$C$8 -> 1243891.2 | E15: =$E$8 -> 1161484 | G15: =$G$8 -> 1156248 | I15: =$I$8 -> 2948182
B16: 人件費 | C16: =$C$14+$C$12 -> 462293.13 | D16: =C16/C17 -> 0.37165078 | E16: =$E$14+$E$12 -> 443491 | F16: =E16/E17 -> 0.38183135 | G16: =$G$14+$G$12 -> 422539 | H16: =G16/G17 -> 0.36543977 | I16: =$I$14+$I$12 -> 1264981 | J16: =I16/I17 -> 0.42907154
B17: ÷ 附加價値額 | C17: =$C$8 -> 1243891.2 | E17: =$E$8 -> 1161484 | G17: =$G$8 -> 1156248 | I17: =$I$8 -> 2948182
A18: 賣出額對比 人件費率 | B18: 勞務費,給與,賞與 | C18: =$C$12 -> 403457.34 | D18: =C18/C19 -> 0.081011707 | E18: =$E$12 -> 393395 | F18: =E18/E19 -> 0.083904828 | G18: =$G$12 -> 360521 | H18: =G18/G19 -> 0.074362178 | I18: =$I$12 -> 1099396 | J18: =I18/I19 -> 0.089058997
B19: ÷ 賣出額 | C19: =$C$9 -> 4980235 | E19: =$E$9 -> 4688586 | G19: =$G$9 -> 4848177 | I19: =$I$9 -> 12344581
B20: 退職, 福利費 | C20: =$C$14 -> 58835.79 | D20: =C20/C21 -> 0.011813858 | E20: =$E$14 -> 50096 | F20: =E20/E21 -> 0.010684671 | G20: =$G$14 -> 62018 | H20: =G20/G21 -> 0.012792025 | I20: =$I$14 -> 165585 | J20: =I20/I21 -> 0.013413578
B21: ÷ 賣出額 | C21: =$C$9 -> 4980235 | E21: =$E$9 -> 4688586 | G21: =$G$9 -> 4848177 | I21: =$I$9 -> 12344581
B22: 人件費 | C22: =$C$20+$C$18 -> 462293.13 | D22: =C22/C23 -> 0.092825565 | E22: =$E$20+$E$18 -> 443491 | F22: =E22/E23 -> 0.094589499 | G22: =$G$20+$G$18 -> 422539 | H22: =G22/G23 -> 0.087154202 | I22: =$I$20+$I$18 -> 1264981 | J22: =I22/I23 -> 0.10247257
B23: ÷ 賣出額 | C23: =$C$9 -> 4980235 | E23: =$E$9 -> 4688586 | G23: =$G$9 -> 4848177 | I23: =$I$9 -> 12344581
A24: 1人當 賃金水準 | B24: 勞務費,給與,賞與(A) | C24: =$C$12 -> 403457.34 | D24: =C24/C25 -> 3955.4641 | E24: =$E$12 -> 393395 | F24: =E24/E25 -> 3856.8137 | G24: =$G$12 -> 360521 | H24: =G24/G25 -> 3534.5196 | I24: =$I$12 -> 1099396 | J24: =I24/I25 -> 3569.4675
B25: ÷ 常時 從業員數 | C25: =$C$11 -> 102 | E25: =$E$11 -> 102 | G25: =$G$11 -> 102 | I25: =$I$11 -> 308 | O25: =O7 -> 46023 | P25: =P7 -> 46054 | Q25: =Q7 -> 46082 | R25: =R7 -> 46113 | S25: =S7 -> 46143 | T25: =T7 -> 46174 | U25: =U7 -> 46204 | V25: =V7 -> 46235 | ... Z25: =Z7 -> 46357
B26: 退職金(B) | C26: 31796.587 | D26: =C26/C27 -> 311.73125 | E26: 31796 | F26: =E26/E27 -> 311.72549 | G26: ='노동2603실적(사업부별)'!$G$26 -> 31796 | H26: =G26/G27 -> 311.72549 | I26: =SUBTOTAL(109,$O$26:$Z$26) -> 91136 | J26: =I26/I27 -> 295.8961 | O26: ='노동2603실적(사업부별)'!N$26 -> 30116 | P26: ='노동2603실적(사업부별)'!O$26 -> 29224 | Q26: ='노동2603실적(사업부별)'!P$26 -> 31796 | R26: ='노동2603실적(사업부별)'!Q$26 -> 0 | S26: ='노동2603실적(사업부별)'!R$26 -> 0 | T26: ='노동2603실적(사업부별)'!S$26 -> 0 | U26: ='노동2603실적(사업부별)'!T$26 -> 0 | V26: ='노동2603실적(사업부별)'!U$26 -> 0 | ... Z26: ='노동2603실적(사업부별)'!Y$26 -> 0
B27: ÷ 常時從業員數 | C27: =$C$11 -> 102 | E27: =$E$11 -> 102 | G27: =$G$11 -> 102 | I27: =$I$11 -> 308
B28: (A) + (B) | C28: =$C$26+$C$24 -> 435253.93 | D28: =C28/C29 -> 4267.1954 | E28: =$E$26+$E$24 -> 425191 | F28: =E28/E29 -> 4168.5392 | G28: =$G$26+$G$24 -> 392317 | H28: =G28/G29 -> 3846.2451 | I28: =$I$26+$I$24 -> 1190532 | J28: =I28/I29 -> 3865.3636
B29: ÷ 常時從業員數 | C29: =$C$11 -> 102 | E29: =$E$11 -> 102 | G29: =$G$11 -> 102 | I29: =$I$11 -> 308
A31: 區 分 | B31: 算 式 | C31: ='노동2603실적(사업부별)'!$C$31 -> 2025年 實積 | E31: ='노동2603실적(사업부별)'!$E$31 -> 2026年 計劃 | G31: ='노동2603실적(사업부별)'!$G$31 -> 3 | I31: 最近 1年間 實積 | K31: 備考 | O31: =O$25 -> 46023 | P31: ='노동2603실적(사업부별)'!O$31 -> 46054 | Q31: ='노동2603실적(사업부별)'!P$31 -> 46082 | R31: ='노동2603실적(사업부별)'!Q$31 -> 45748 | S31: ='노동2603실적(사업부별)'!R$31 -> 45778 | T31: ='노동2603실적(사업부별)'!S$31 -> 45809 | U31: ='노동2603실적(사업부별)'!T$31 -> 45839 | V31: ='노동2603실적(사업부별)'!U$31 -> 45870 | W31: ='노동2603실적(사업부별)'!V$31 -> 45901 | ... Z31: ='노동2603실적(사업부별)'!Y$31 -> 45992
A32: 1人當 | B32: 附加價値額 | C32: ='노동2603실적(사업부별)'!C32 -> 22879144 | D32: =C32/C33 -> 215840.98 | E32: ='노동2603실적(사업부별)'!$E$32 -> 12645787 | F32: =E32/E33 -> 129038.64 | G32: =$I$8 -> 2948182 | H32: =G32/G33 -> 28716.058 | I32: =SUBTOTAL(109,$O$32:$Z$32) -> 10512849 | J32: =I32/I33 -> 100441.23 | O32: ='노동2603실적(사업부별)'!N$32 -> 923950 | P32: ='노동2603실적(사업부별)'!O$32 -> 867984 | Q32: ='노동2603실적(사업부별)'!P$32 -> 1156248 | R32: ='노동2603실적(사업부별)'!Q$32 -> 1173741 | S32: ='노동2603실적(사업부별)'!R$32 -> 956633 | T32: ='노동2603실적(사업부별)'!S$32 -> 733807 | U32: ='노동2603실적(사업부별)'!T$32 -> 1026435 | V32: ='노동2603실적(사업부별)'!U$32 -> 927514 | ... Z32: ='노동2603실적(사업부별)'!Y$32 -> 477791
A33: 附加價値額 | B33: ÷ 從業員數 | C33: ='노동2603실적(사업부별)'!C33 -> 106 | E33: ='노동2603실적(사업부별)'!$E$33 -> 98 | G33: =I11/G31 -> 102.66667 | I33: =SUBTOTAL(101,$O$33:$Z$33) -> 104.66667 | O33: ='노동2603실적(사업부별)'!N$33 -> 103 | P33: ='노동2603실적(사업부별)'!O$33 -> 103 | Q33: ='노동2603실적(사업부별)'!P$33 -> 102 | R33: ='노동2603실적(사업부별)'!Q$33 -> 107 | S33: ='노동2603실적(사업부별)'!R$33 -> 105 | T33: ='노동2603실적(사업부별)'!S$33 -> 106 | U33: ='노동2603실적(사업부별)'!T$33 -> 106 | V33: ='노동2603실적(사업부별)'!U$33 -> 105 | ... Z33: ='노동2603실적(사업부별)'!Y$33 -> 104
A35: 2) 生産職分
K36: (單位 : 阡Won, 名, %)
A37: 區 分 | B37: 算 式 | C37: =$C$6 -> 46082 | E37: =$E$6 -> 46082 | G37: =$G$6 -> 46082 | I37: 累計 實績 | K37: 備考
C38: 資料 | D38: 指標 | E38: 資料 | F38: 指標 | G38: 資料 | H38: 指標 | I38: 資料 | J38: 指標 | O38: =O$7 -> 46023 | P38: =P$7 -> 46054 | Q38: =Q$7 -> 46082 | R38: =R$7 -> 46113 | S38: =S$7 -> 46143 | T38: =T$7 -> 46174 | U38: =U$7 -> 46204 | V38: =V$7 -> 46235 | ... Z38: =Z$7 -> 46357
A39: 常時從業員數 | B39: 直接人員(名) | C39: 57 | E39: =G39 -> 58 | G39: ='노동2603실적(사업부별)'!$G$39 -> 58 | I39: =SUBTOTAL(109,$O$39:$Z$39) -> 178 | M39: 2p수정계획 임금 | O39: ='노동2603실적(사업부별)'!N$39 -> 62 | P39: ='노동2603실적(사업부별)'!O$39 -> 58 | Q39: ='노동2603실적(사업부별)'!P$39 -> 58 | R39: ='노동2603실적(사업부별)'!Q$39 -> 0 | S39: ='노동2603실적(사업부별)'!R$39 -> 0 | T39: ='노동2603실적(사업부별)'!S$39 -> 0 | U39: ='노동2603실적(사업부별)'!T$39 -> 0 | V39: ='노동2603실적(사업부별)'!U$39 -> 0 | ... Z39: ='노동2603실적(사업부별)'!Y$39 -> 0
A40: 實作業時間 | C40: =197413/12 -> 16451.083 | E40: ='노무비(인원,근무시간 등(25_01)'!$I$20 -> 16157.9 | G40: ='노동2603실적(사업부별)'!$G$40 -> 15415.5 | I40: =SUBTOTAL(109,$O$40:$Z$40) -> 41888.5 | M40: 170105 | O40: ='노동2603실적(사업부별)'!N$40 -> 13731 | P40: ='노동2603실적(사업부별)'!O$40 -> 12742 | Q40: ='노동2603실적(사업부별)'!P$40 -> 15415.5 | R40: ='노동2603실적(사업부별)'!Q$40 -> 0 | S40: ='노동2603실적(사업부별)'!R$40 -> 0 | T40: ='노동2603실적(사업부별)'!S$40 -> 0 | U40: ='노동2603실적(사업부별)'!T$40 -> 0 | V40: ='노동2603실적(사업부별)'!U$40 -> 0 | ... Z40: ='노동2603실적(사업부별)'!Y$40 -> 0
A41: 時間當賃率 | B41: 勞務費,給與,賞與 | C41: =$M$40+'노무비(인원,근무시간 등(25_01)'!$C$24 -> 237222.34 | D41: =C41/C42 -> 14.419861 | E41: =$M$42+'노무비(25-05)'!$K$23 -> 218364 | F41: =E41/E42 -> 13.51438 | G41: ='노동2603실적(사업부별)'!$G$41 -> 191405 | H41: =G41/G42 -> 12.416399 | I41: =SUBTOTAL(109,$O$41:$Z$41) -> 503535 | J41: =I41/I42 -> 12.020841 | M41: 1p수정계획 임금 | O41: ='노동2603실적(사업부별)'!N$41 -> 117127 | P41: ='노동2603실적(사업부별)'!O$41 -> 195003 | Q41: ='노동2603실적(사업부별)'!P$41 -> 191405 | R41: ='노동2603실적(사업부별)'!Q$41 -> 0 | S41: ='노동2603실적(사업부별)'!R$41 -> 0 | T41: ='노동2603실적(사업부별)'!S$41 -> 0 | U41: ='노동2603실적(사업부별)'!T$41 -> 0 | V41: ='노동2603실적(사업부별)'!U$41 -> 0 | ... Z41: ='노동2603실적(사업부별)'!Y$41 -> 0
B42: ÷ 實作業時間 | C42: =$C$40 -> 16451.083 | E42: =E40 -> 16157.9 | G42: =$G$40 -> 15415.5 | I42: =$I$40 -> 41888.5 | M42: 189898
A43: 1人 月生産金額 | B43: 生産金額 | C43: 2895255 | D43: =C43/C44 -> 50793.947 | E43: 2773544 | F43: =E43/E44 -> 47819.724 | G43: ='노동2603실적(사업부별)'!$G$43 -> 2698088 | H43: =G43/G44 -> 46518.759 | I43: ='노동2603실적(사업부별)'!$I$43 -> 6935679 | J43: =I43/I44 -> 38964.489 | O43: ='노동2603실적(사업부별)'!N$43 -> 2211637 | P43: ='노동2603실적(사업부별)'!O$43 -> 2025954 | Q43: ='노동2603실적(사업부별)'!P$43 -> 2698088 | R43: ='노동2603실적(사업부별)'!Q$43 -> 0 | S43: ='노동2603실적(사업부별)'!R$43 -> 0 | T43: ='노동2603실적(사업부별)'!S$43 -> 0 | U43: ='노동2603실적(사업부별)'!T$43 -> 0 | V43: ='노동2603실적(사업부별)'!U$43 -> 0 | ... Z43: ='노동2603실적(사업부별)'!Y$43 -> 0
B44: ÷ 常時從業員數 | C44: =$C$39 -> 57 | E44: =$E$39 -> 58 | G44: =G39 -> 58 | I44: =$I$39 -> 178
...

Sheet 노동2603실적(사업부별)
A3: (6.2) 事業部別
A4: 1) 任職員 包含
K5: (單位 : 阡Won, 名, %)
A6: 區 分 | B6: 算 式 | C6: RKM | E6: HKMC | G6: 計 | I6: 累計 實績 | K6: 備考
C7: 資料 | D7: 指標 | E7: 資料 | F7: 指標 | G7: 資料 | H7: 指標 | I7: 資料 | J7: 指標 | N7: 46023 | O7: 46054 | P7: 46082 | Q7: 46113 | R7: 46143 | S7: 46174 | T7: 46204 | U7: 46235 | V7: 46266 | W7: 46296 | X7: 46327 | Y7: 46357
A8: 附加價値率 | B8: 附加價値額 | C8: 904594 | D8: =C8/C9 -> 0.25822303 | E8: 251654 | F8: =E8/E9 -> 0.18709959 | G8: =$C$8+$E$8 -> 1156248 | H8: =G8/G9 -> 0.23849129 | I8: =SUBTOTAL(109,$N$8:$Y$8) -> 2948182 | J8: =I8/I9 -> 0.23882398 | N8: 923950 | O8: 867984 | P8: 1156248
B9: ÷ 賣出額 | C9: 3503150 | E9: 1345027 | G9: =$C$9+$E$9 -> 4848177 | I9: =SUBTOTAL(109,$N$9:$Y$9) -> 12344581 | N9: 3925072 | O9: 3571332 | P9: 4848177
A10: 勞動生産性 | B10: 附加價値額 | C10: =$C$8 -> 904594 | D10: =C10/C11 -> 16228.725 | E10: =$E$8 -> 251654 | F10: =E10/E11 -> 5440.0267 | G10: =$G$8 -> 1156248 | H10: =G10/G11 -> 11335.765 | I10: =$I$8 -> 2948182 | J10: =I10/I11 -> 9572.0195 | N10: =N$7 -> 46023 | O10: =O$7 -> 46054 | P10: =P$7 -> 46082 | Q10: =Q$7 -> 46113 | R10: =R$7 -> 46143 | S10: =S$7 -> 46174 | T10: =T$7 -> 46204 | U10: =U$7 -> 46235 | ... Y10: =Y$7 -> 46357
B11: ÷ 常時 從業員數 | C11: ='노무비(인원,근무시간 등(25_01)'!$C$6 -> 55.7403 | E11: ='노무비(인원,근무시간 등(25_01)'!$D$6 -> 46.2597 | G11: =$C$11+$E$11 -> 102 | I11: =SUBTOTAL(109,$N$11:$Y$11) -> 308 | N11: 103 | O11: 103 | P11: 102
A12: 勤勞所得 配分率 | B12: 勞務費,給與,賞與 | C12: 228065 | D12: =C12/C13 -> 0.25211863 | E12: 132456 | F12: =E12/E13 -> 0.52634172 | G12: =$C$12+$E$12 -> 360521 | H12: =G12/G13 -> 0.31180249 | I12: =SUBTOTAL(109,$N$12:$Y$12) -> 1099396 | J12: =I12/I13 -> 0.37290642 | N12: 371215 | O12: 367660 | P12: 360521
B13: ÷ 附加價値額 | C13: =$C$8 -> 904594 | E13: =$E$8 -> 251654 | G13: =$G$8 -> 1156248 | I13: =$I$8 -> 2948182 | N13: =N$7 -> 46023 | O13: =O$7 -> 46054 | P13: =P$7 -> 46082 | Q13: =Q$7 -> 46113 | R13: =R$7 -> 46143 | S13: =S$7 -> 46174 | T13: =T$7 -> 46204 | U13: =U$7 -> 46235 | ... Y13: =Y$7 -> 46357
B14: 退職, 福利費 | C14: 49318 | D14: =C14/C15 -> 0.054519486 | E14: 12700 | F14: =E14/E15 -> 0.050466116 | G14: =$C$14+$E$14 -> 62018 | H14: =G14/G15 -> 0.053637282 | I14: =SUBTOTAL(109,$N$14:$Y$14) -> 165585 | J14: =I14/I15 -> 0.056165121 | N14: 48058 | O14: 55509 | P14: 62018
B15: ÷ 附加價値額 | C15: =$C$8 -> 904594 | E15: =$E$8 -> 251654 | G15: =$G$8 -> 1156248 | I15: =$I$8 -> 2948182
B16: 人件費 | C16: =$C$14+$C$12 -> 277383 | D16: =C16/C17 -> 0.30663812 | E16: =$E$14+$E$12 -> 145156 | F16: =E16/E17 -> 0.57680784 | G16: =$G$14+$G$12 -> 422539 | H16: =G16/G17 -> 0.36543977 | I16: =$I$14+$I$12 -> 1264981 | J16: =I16/I17 -> 0.42907154
B17: ÷ 附加價値額 | C17: =$C$8 -> 904594 | E17: =$E$8 -> 251654 | G17: =$G$8 -> 1156248 | I17: =$I$8 -> 2948182
A18: 賣出額對比 人件費率 | B18: 勞務費,給與,賞與 | C18: =$C$12 -> 228065 | D18: =C18/C19 -> 0.065102836 | E18: =$E$12 -> 132456 | F18: =E18/E19 -> 0.098478321 | G18: =$G$12 -> 360521 | H18: =G18/G19 -> 0.074362178 | I18: =$I$12 -> 1099396 | J18: =I18/I19 -> 0.089058997
B19: ÷ 賣出額 | C19: =$C$9 -> 3503150 | E19: =$E$9 -> 1345027 | G19: =$G$9 -> 4848177 | I19: =$I$9 -> 12344581
B20: 退職, 福利費 | C20: =$C$14 -> 49318 | D20: =C20/C21 -> 0.014078187 | E20: =$E$14 -> 12700 | F20: =E20/E21 -> 0.0094421896 | G20: =$G$14 -> 62018 | H20: =G20/G21 -> 0.012792025 | I20: =$I$14 -> 165585 | J20: =I20/I21 -> 0.013413578
B21: ÷ 賣出額 | C21: =$C$9 -> 3503150 | E21: =$E$9 -> 1345027 | G21: =$G$9 -> 4848177 | I21: =$I$9 -> 12344581
B22: 人件費 | C22: =$C$20+$C$18 -> 277383 | D22: =C22/C23 -> 0.079181023 | E22: =$E$20+$E$18 -> 145156 | F22: =E22/E23 -> 0.10792051 | G22: =$G$20+$G$18 -> 422539 | H22: =G22/G23 -> 0.087154202 | I22: =$I$20+$I$18 -> 1264981 | J22: =I22/I23 -> 0.10247257
B23: ÷ 賣出額 | C23: =$C$9 -> 3503150 | E23: =$E$9 -> 1345027 | G23: =$G$9 -> 4848177 | I23: =$I$9 -> 12344581
A24: 1人當 賃金水準 | B24: 勞務費,給與,賞與(A) | C24: =$C$12 -> 228065 | D24: =C24/C25 -> 4091.5639 | E24: =$E$12 -> 132456 | F24: =E24/E25 -> 2863.313 | G24: =$G$12 -> 360521 | H24: =G24/G25 -> 3534.5196 | I24: =$I$12 -> 1099396 | J24: =I24/I25 -> 3569.4675
B25: ÷ 常時 從業員數 | C25: =$C$11 -> 55.7403 | E25: =$E$11 -> 46.2597 | G25: =$G$11 -> 102 | I25: =$I$11 -> 308 | N25: =N$7 -> 46023 | O25: =O$7 -> 46054 | P25: =P$7 -> 46082 | Q25: =Q$7 -> 46113 | R25: =R$7 -> 46143 | S25: =S$7 -> 46174 | T25: =T$7 -> 46204 | U25: =U$7 -> 46235 | ... Y25: =Y$7 -> 46357
B26: 退職金(B) | C26: 21456 | D26: =C26/C27 -> 384.92796 | E26: 10340 | F26: =E26/E27 -> 223.52069 | G26: =$C$26+$E$26 -> 31796 | H26: =G26/G27 -> 311.72549 | I26: =SUBTOTAL(109,$N$26:$Y$26) -> 91136 | J26: =I26/I27 -> 295.8961 | N26: 30116 | O26: 29224 | P26: 31796
B27: ÷ 常時從業員數 | C27: =$C$11 -> 55.7403 | E27: =$E$11 -> 46.2597 | G27: =$G$11 -> 102 | I27: =$I$11 -> 308
B28: (A) + (B) | C28: =$C$26+$C$24 -> 249521 | D28: =C28/C29 -> 4476.4919 | E28: =$E$26+$E$24 -> 142796 | F28: =E28/E29 -> 3086.8337 | G28: =$G$24+$G$26 -> 392317 | H28: =G28/G29 -> 3846.2451 | I28: =$I$26+$I$24 -> 1190532 | J28: =I28/I29 -> 3865.3636
B29: ÷ 常時從業員數 | C29: =$C$11 -> 55.7403 | E29: =$E$11 -> 46.2597 | G29: =$G$11 -> 102 | I29: =$I$11 -> 308
A31: 區 分 | B31: 算 式 | C31: 2025年 實積 | E31: 2026年 計劃 | G31: 3 | I31: 最近 1年間 實積 | K31: 備考 | N31: =N$7 -> 46023 | O31: =O$7 -> 46054 | P31: =P$7 -> 46082 | Q31: 45748 | R31: 45778 | S31: 45809 | T31: 45839 | U31: 45870 | V31: 45901 | W31: 45931 | X31: 45962 | Y31: 45992
A32: 1人當 | B32: 附加價値額 | C32: 22879144 | D32: =C32/C33 -> 215840.98 | E32: 12645787 | F32: =E32/E33 -> 129038.64 | G32: =$I$8 -> 2948182 | H32: =G32/G33 -> 28716.058 | I32: =SUBTOTAL(109,$N$32:$Y$32) -> 10512849 | J32: =I32/I33 -> 100441.23 | N32: =N$8 -> 923950 | O32: =O$8 -> 867984 | P32: =P$8 -> 1156248 | Q32: 1173741 | R32: 956633 | S32: 733807 | T32: 1026435 | U32: 927514 | V32: 799312 | W32: 632571 | X32: 836863 | Y32: 477791
A33: 附加價値額 | B33: ÷ 從業員數 | C33: 106 | E33: 98 | G33: =I11/G31 -> 102.66667 | I33: =SUBTOTAL(101,$N$33:$Y$33) -> 104.66667 | N33: =N$11 -> 103 | O33: =O$11 -> 103 | P33: =P$11 -> 102 | Q33: 107 | R33: 105 | S33: 106 | T33: 106 | U33: 105 | V33: 106 | W33: 105 | X33: 104 | Y33: 104
C34: 고정 값 | E34: 고정 값
A35: 2) 生産職分
K36: (單位 : 阡Won, 名, %)
A37: 區 分 | B37: 算 式 | C37: =+C6 -> RKM | E37: =+E6 -> HKMC | G37: =+G6 -> 計 | I37: 累計 實績 | K37: 備考
C38: 資料 | D38: 指標 | E38: 資料 | F38: 指標 | G38: 資料 | H38: 指標 | I38: 資料 | J38: 指標 | N38: =N$7 -> 46023 | O38: =O$7 -> 46054 | P38: =P$7 -> 46082 | Q38: =Q$7 -> 46113 | R38: =R$7 -> 46143 | S38: =S$7 -> 46174 | T38: =T$7 -> 46204 | U38: =U$7 -> 46235 | ... Y38: =Y$7 -> 46357
A39: 常時從業員數 | B39: 直接人員(名) | C39: ='노무비(인원,근무시간 등(25_01)'!$C$5 -> 33.004497 | E39: ='노무비(인원,근무시간 등(25_01)'!$D$5 -> 24.995503 | G39: =$C$39+$E$39 -> 58 | I39: =SUBTOTAL(109,$N$39:$Y$39) -> 178 | M39: 1p ⑬ | N39: 62 | O39: 58 | P39: 58
A40: 實作業時間 | C40: ='노무비(인원,근무시간 등(25_01)'!$C$16 -> 8772.0832 | E40: ='노무비(인원,근무시간 등(25_01)'!$C$17 -> 6643.4168 | G40: =$C$40+$E$40 -> 15415.5 | I40: =SUBTOTAL(109,$N$40:$Y$40) -> 41888.5 | M40: 118114 | N40: 13731 | O40: 12742 | P40: 15415.5
A41: 時間當賃率 | B41: 勞務費,給與,賞與 | C41: =$M$40+'노무비(25-05)'!$E$8 -> 137233 | D41: =C41/C42 -> 15.644288 | E41: =$M$42+'노무비(25-05)'!$J$8 -> 54172 | F41: =E41/E42 -> 8.1542378 | G41: =$C$41+$E$41 -> 191405 | H41: =G41/G42 -> 12.416399 | I41: =SUBTOTAL(109,$N$41:$Y$41) -> 503535 | J41: =I41/I42 -> 12.020841 | M41: 1p ⑭ | N41: 117127 | O41: 195003 | P41: 191405
B42: ÷ 實作業時間 | C42: =$C$40 -> 8772.0832 | E42: =$E$40 -> 6643.4168 | G42: =$G$40 -> 15415.5 | I42: =$I$40 -> 41888.5 | M42: 44824 | N42: =N$7 -> 46023 | O42: =O$7 -> 46054 | P42: =P$7 -> 46082 | Q42: =Q$7 -> 46113 | R42: =R$7 -> 46143 | S42: =S$7 -> 46174 | T42: =T$7 -> 46204 | U42: =U$7 -> 46235 | ... Y42: =Y$7 -> 46357
A43: 1人 月生産金額 | B43: 生産金額 | C43: 1518529 | D43: =C43/C44 -> 46009.76 | E43: 1179559 | F43: =E43/E44 -> 47190.849 | G43: =$C$43+$E$43 -> 2698088 | H43: =G43/G44 -> 46518.759 | I43: =SUBTOTAL(109,$N$43:$Y$43) -> 6935679 | J43: =I43/I44 -> 38964.489 | N43: 2211637 | O43: 2025954 | P43: 2698088
...

Sheet 노무비(25-05)
A1: <26년 03월 노무비> | K1: 3 페이지
B3: [상여 및 퇴직급여 구분] 실적 | G3: [상여 및 퇴직급여 구분] 실적
D4: <RKM> | I4: <HKMC>
B6: 구분 | D6: 번호 | E6: 금액 | G6: 구분 | I6: 번호 | J6: 금액
B7: 상여금 | C7: 사무직 | G7: 상여금 | H7: 사무직 | K7: =E7+J7 -> 0
C8: 생산직 | D8: 15 | E8: =E9-E7 -> 19119 | H8: 생산직 | I8: 16 | J8: =J9-J7 -> 9348 | K8: =E8+J8 -> 28467
B9: 계 | E9: 19119 | G9: 계 | J9: 9348 | K9: =SUM(K7:K8) -> 28467 | L9: 퇴직급여
L10: <RKM> | N10: <HKMC>
N11: 신재만 | O11: 5331580
B12: 구분 | D12: 번호 | E12: 금액 | G12: 구분 | I12: 번호 | J12: 금액 | L12: 이광호 | M12: 4525110 | N12: 이대호 | O12: 3576270
B13: 퇴직급여 | C13: 사무직 | E13: =$M$27 -> 2179.1783 | G13: 퇴직급여 | H13: 사무직 | J13: =O27 -> 2445.4492 | K13: =E13+J13 -> 4624.6275 | L13: 박상미 | M13: 3596800 | N13: 임재홍 | O13: 3570020
C14: 생산직 | D14: 11 | E14: =E15-E13 -> 14486.822 | H14: 생산직 | I14: 12 | J14: =J15-J13 -> 4070.5508 | K14: =E14+J14 -> 18557.373 | N14: 임정근 | O14: 3515310
B15: 계 | E15: 16666 | G15: 계 | J15: 6516 | K15: =SUM(K13:K14) -> 23182 | N15: 이혜원 | O15: 3057730
L17: 유희문 | M17: 3664020
B18: [상여 및 퇴직급여 구분] 계획 | G18: [상여 및 퇴직급여 구분] 계획 | L18: 오택민 | M18: 4593770
D19: <RKM> | I19: <HKMC> | L19: 황성현 | M19: 3724850
N20: 김도훈 | O20: 4190200
B21: 구분 | D21: 번호 | E21: 금액 | G21: 구분 | I21: 번호 | J21: 금액 | L21: 이권희 | M21: 2848370 | N21: 장상훈 | O21: 3046550
B22: 상여금 | C22: 사무직 | E22: =$E$7 -> 0 | G22: 상여금 | H22: 사무직 | J22: =$J$7 -> 0 | K22: =E22+J22 -> 0 | L22: 황상석 | M22: 3197220 | N22: 오세범 | O22: 3057730
C23: 생산직 | D23: 18 | E23: =E24-E22 -> 19118 | H23: 생산직 | I23: 19 | J23: =J24-J22 -> 9348 | K23: =E23+J23 -> 28466
B24: 계 | E24: 19118 | G24: 계 | J24: 9348 | K24: =SUM(K22:K23) -> 28466
M25: =SUM(M11:M24) -> 26150140 | O25: =SUM(O11:O24) -> 29345390
L26: 12 | M26: =M25/$L$26 -> 2179178.3 | O26: =O25/$L$26 -> 2445449.2
B27: 구분 | D27: 번호 | E27: 금액 | G27: 구분 | I27: 번호 | J27: 금액 | M27: =M26/1000 -> 2179.1783 | O27: =O26/1000 -> 2445.4492
B28: 퇴직급여 | C28: 사무직 | E28: =$E$13 -> 2179.1783 | G28: 퇴직급여 | H28: 사무직 | J28: =$J$13 -> 2445.4492 | K28: =J28+E28 -> 4624.6275
C29: 생산직 | D29: 20 | E29: =E30-E28 -> -2179.1783 | H29: 생산직 | I29: 21 | J29: =J30-J28 -> -2445.4492 | K29: =J29+E29 -> -4624.6275
B30: 계 | G30: 계 | K30: =SUM(K28:K29) -> 0
B35: * 퇴직급여는 매달 변동. 사무직 급여가 일정하니 사무직 급여를 기본 셋팅하여 생산직은 차액 금액 넣음.

Sheet 노무비(인원,근무시간 등(25_01)
A1: 26년 03월 노무비(인원,근무시간 등) | F1: 4 페이지
C2: =$E$2-D2 -> 0.5167228 | D2: =$F$2/$G$2 -> 0.4832772 | E2: 1 | F2: 574157 | G2: 1188049
A3: 03月 | C3: RKM | D3: HKMC | E3: 합계
B4: 관리 | C4: =$E$4*C2 -> 22.735803 | D4: =$E$4*D2 -> 21.264197 | E4: =41+3 -> 44 | F4: 입사 : | H4: 퇴사 :
B5: 생산 | C5: =$E$5*C7 -> 33.004497 | D5: =$E$5*D7 -> 24.995503 | E5: =45+13 -> 58 | F5: 입사 : | H5: 퇴사 :
C6: =SUM(C4:C5) -> 55.7403 | D6: =SUM(D4:D5) -> 46.2597 | E6: =SUM(E4:E5) -> 102 | F6: 제외 :
C7: =$E$2-D7 -> 0.56904306 | D7: =$F$7/$G$7 -> 0.43095694 | F7: 46764 | G7: 108512
F15: 총 잔업시간 | G15: 기본근로시간
A16: 근무시간 | B16: RKM | C16: =$E$18*C7 -> 8772.0832 | E16: =SUM(F16:G16) -> 11465.5 | F16: =808+194+734.5+9 -> 1745.5 | G16: =7448+2272 -> 9720 | H16: 김해
B17: HKMC | C17: =$E$18*D7 -> 6643.4168 | E17: =SUM(F17:G17) -> 3950 | F17: =482.5+586.5+72+1 -> 1142 | G17: =2176+632 -> 2808 | H17: 부산
B18: 합계 | C18: =C16+C17 -> 15415.5 | E18: =E16+E17 -> 15415.5 | F18: =SUM(F16:F17) -> 2887.5
F19: (당월) 생산인원*8*근무일수(주차, 유급포함) | G19: 총 잔업시간
E20: =$E$5 -> 58 | F20: =(E20*8*26)*1.1 -> 13270.4 | G20: =$F$18 -> 2887.5 | I20: =SUM(F20:G20) -> 16157.9
I21: 실 작업시간
A22: 기본급 1/2 | B22: RKM | C22: =$E$24*C7 -> 38192.656 | E22: =(F22/2)/1000 -> 52057.365 | F22: 104114730 | G22: =F22/2 -> 52057365 | H22: 김해
B23: HKMC | C23: =$E$24*D7 -> 28924.684 | E23: =(F23/2)/1000 -> 15059.975 | F23: 30119950 | G23: =F23/2 -> 15059975 | H23: 부산
B24: 합계 | C24: =C22+C23 -> 67117.34 | E24: =E22+E23 -> 67117.34
